<?xml version="1.0" encoding="UTF-8"?>
<!-- Generated by org.testng.reporters.JUnitReportReporter -->
<testsuite hostname="DESKTOP-E69K95O" name="com.saucedemo.Test.validateLoginData" tests="4" failures="1" timestamp="16 Oct 2021 17:37:16 GMT" time="14.611" errors="0">
  <testcase name="validatePositiveLogin" time="2.426" classname="com.saucedemo.Test.validateLoginData"/>
  <testcase name="validatLockedOutUserLogin" time="2.322" classname="com.saucedemo.Test.validateLoginData"/>
  <testcase name="validatglitchUserLogin" time="7.434" classname="com.saucedemo.Test.validateLoginData">
    <failure type="java.lang.AssertionError" message="expected [https://www.saucedemo.com/inventor.html] but found [https://www.saucedemo.com/inventory.html]">
      <![CDATA[java.lang.AssertionError: expected [https://www.saucedemo.com/inventor.html] but found [https://www.saucedemo.com/inventory.html]
	at org.testng.Assert.fail(Assert.java:94)
	at org.testng.Assert.failNotEquals(Assert.java:496)
	at org.testng.Assert.assertEquals(Assert.java:125)
	at org.testng.Assert.assertEquals(Assert.java:178)
	at org.testng.Assert.assertEquals(Assert.java:188)
	at com.saucedemo.Test.validateLoginData.validatglitchUserLogin(validateLoginData.java:119)
	at sun.reflect.NativeMethodAccessorImpl.invoke0(Native Method)
	at sun.reflect.NativeMethodAccessorImpl.invoke(Unknown Source)
	at sun.reflect.DelegatingMethodAccessorImpl.invoke(Unknown Source)
	at java.lang.reflect.Method.invoke(Unknown Source)
	at org.testng.internal.MethodInvocationHelper.invokeMethod(MethodInvocationHelper.java:85)
	at org.testng.internal.Invoker.invokeMethod(Invoker.java:639)
	at org.testng.internal.Invoker.invokeTestMethod(Invoker.java:816)
	at org.testng.internal.Invoker.invokeTestMethods(Invoker.java:1124)
	at org.testng.internal.TestMethodWorker.invokeTestMethods(TestMethodWorker.java:125)
	at org.testng.internal.TestMethodWorker.run(TestMethodWorker.java:108)
	at org.testng.TestRunner.privateRun(TestRunner.java:774)
	at org.testng.TestRunner.run(TestRunner.java:624)
	at org.testng.SuiteRunner.runTest(SuiteRunner.java:359)
	at org.testng.SuiteRunner.runSequentially(SuiteRunner.java:354)
	at org.testng.SuiteRunner.privateRun(SuiteRunner.java:312)
	at org.testng.SuiteRunner.run(SuiteRunner.java:261)
	at org.testng.SuiteRunnerWorker.runSuite(SuiteRunnerWorker.java:52)
	at org.testng.SuiteRunnerWorker.run(SuiteRunnerWorker.java:86)
	at org.testng.TestNG.runSuitesSequentially(TestNG.java:1215)
	at org.testng.TestNG.runSuitesLocally(TestNG.java:1140)
	at org.testng.TestNG.run(TestNG.java:1048)
	at org.testng.remote.AbstractRemoteTestNG.run(AbstractRemoteTestNG.java:115)
	at org.testng.remote.RemoteTestNG.initAndRun(RemoteTestNG.java:251)
	at org.testng.remote.RemoteTestNG.main(RemoteTestNG.java:77)
]]>
    </failure>
  </testcase> <!-- validatglitchUserLogin -->
  <testcase name="validatProblemUserLogin" time="2.429" classname="com.saucedemo.Test.validateLoginData"/>
</testsuite> <!-- com.saucedemo.Test.validateLoginData -->
